Workbook
Name codes: Specifications!$A$4:$A$5
Name list: [1]Specifications!$A$11:$A$13
Name list: [1]Specifications!$A$11:$A$13
Name list: [2]Specifications!$A$11:$A$13
Name list: Specifications!$A$11:$A$25
Name NAcheck: '[3]Reference - DO NOT PRINT'!$B$27:$B$29
Name NALFI: '[3]Reference - DO NOT PRINT'!$B$32:$B$34
Name NANCR: '[4]Reference - DO NOT PRINT'!$B$6:$B$8
Name NPR: '[3]Reference - DO NOT PRINT'!$B$51:$B$53
Name passfail: '[3]Reference - DO NOT PRINT'!$B$2:$B$4
Name pm: '[3]Reference - DO NOT PRINT'!$B$41:$B$43
Name PRF: '[3]Reference - DO NOT PRINT'!$B$36:$B$39
Name STcheck: '[3]Reference - DO NOT PRINT'!$B$46:$B$48
Name yn: '[3]Reference - DO NOT PRINT'!$B$10:$B$13
Name ynrsr: '[3]Reference - DO NOT PRINT'!$B$16:$B$19

Sheet Intended Use
A1: Intended Use
A2: This worksheet is associated with MTB Ultra V2 Product QC Testing Procedure (D25862).
A4: Fields in blue must be input electronically.
A5: Fields in green may be entered manually.
A6: Fields in yellow perform calculations.
A9: Mean Ct Evaluation
A10: This tab calculates the mean Ct for SPC and the mean IS1081-IS6110 Ct from Negative samples. It will calculate the mean Ct and mean TM for IS1081-IS6110, rpo1, rpo2, rpo4 from Sample Type 1 as well as the mean Ct and mean TM for IS1081-IS6110, rpo1, rpo2, rpo3, rpo4 from Sample Type 2 and compares them to specifications on "Specifications" tab. Failing results are highlighted in RED.
A11: This tab performs the same calculations for the "First 10" results | N11: Table of Tabs to Print-SV only
A12: Vacuum Seal Data | N12: Tab | O12: Print or Not Print
A13: This tab is used to record and evaluate the Vacuum Seal Test data from ROBAL in-process testing. | N13: Intended Use | O13: Do NOT print
B14: Column A | N14: Mean Ct Evaluation | O14: Print
B15: Enumerates the sampled cartridges. | N15: Vacuum Seal Data | O15: Print
N16: Test Summary | O16: Print
B17: Column B | N17: Data Summary | O17: Print
B18: Records the Cartridge ID. | N18: Data- First 10 | O18: Print
N19: Data- Sample Type 0 | O19: Print
B20: Column C | N20: Data- Sample Type 1 | O20: Print
B21: Records the results of seal test. | N21: Data- Sample Type 2 | O21: Print
B22: Valid entries are: | N22: Data- Replaced | O22: Print
C23: "P" | N23: Statistical Process Control | O23: Print
C24: "F" | N24: Resample Vacuum Seal Data | O24: Print if applicable
C25: "N" | N25: Resample Mean Ct Evaluation | O25: Print if applicable
N26: Resample Data Summary | O26: Print if applicable
B27: Column D | N27: Data- Resample Replaced | O27: Print if applicable
B28: Calculates the results of seal test. | N28: Specifications | O28: Do NOT print
B29: The result is "NA" if the test replicate was not tested or does not apply. | N29: HistoricalAccuStats | O29: Do NOT print
B30: The results of the calculations are used as a counter for internal worksheet purposes. | N30: For Reference Only | O30: Do NOT print
A31: Test Summary
A32: B3 | B32: Select Catalog Number from pull down menu
A33: B4 | B33: Enter lot number (without leading 0)
A34: Row 9 and 11 | B34: Enter Control lot number
A35: Row 15-16 | B35: Enter pipet information
A36: Row 18-21 | B36: Enter GeneXpert information
A37: P18 | B37: Enter bags tested using infinity
A39: A23-G32 | B39: Table 4
B40: column C | C40: Counts individual error types from data summary tab
B41: column D | C41: Compares number of failures to pass/resample criteria (N>4 resample)
B42: column E | C42: Counts individual error types from resample data summary tab
B43: coulmn F | C43: Compares number of failures to pass/resample criteria (N>10 resample)
A44: C34 | B44: Counts the max count for Single Minor Failure
...

Sheet Test Summary
A1: Product QC Testing Summary
A3: Product Catalog/Part No.: | B3: GXMTBRIFULTRA50 | E3: (Select using drop-down menu.) | H3: Type of Resample | J3: NA
A4: Cartridge No. (LSP) | B4: 92303 | E4: Expiration Date | G4: 46488
A6: Table 1; Test and Control Material Information
A7: TB1081-MDR2 Cells | C7: TET Buffer | E7: Sample Reagent | H7: Sample Reagent
A8: Part No.* | B8: Lot No. | C8: Part No.* | D8: Lot No. | E8: Part No.* | F8: Lot No. | G8: Bag # | H8: Part No.* | I8: Lot No. | J8: Bag #
A9: 001-1923 | B9: C15NOV23D | C9: 500-1315 or 500-0995 | D9: 1001500034 | E9: 500-2095, 500-2290, 500-2608, 700-5208, 700-6052 or 700-9287,700-8870 | F9: 1001499559 | G9: 00+05-10+TBWT | H9: 500-2095, 500-2290, 500-2608, 700-5208, 700-6052 or 700-9287,700-8870 | I9: 1001502674 | J9: 01-02
A10: TBWT Cells | E10: Sample Reagent | H10: Sample Reagent
A11: Part No.* | B11: Lot No. | E11: Part No.* | F11: Lot No. | G11: Bag # | H11: Part No.* | I11: Lot No. | J11: Bag #
A12: 001-1968 | B12: B01NOV24D | E12: 500-2095, 500-2290, 500-2608, 700-5208, 700-6052 or 700-9287,700-8870 | F12: 1001501891 | G12: 03-04 | H12: 500-2095, 500-2290, 500-2608, 700-5208, 700-6052 or 700-9287,700-8870 | I12: N/A | J12: N/A
A13: * Circle one, if more than 1 option is displayed.
A14: Table 2; Pipette Information
A15: Cepheid ID | B15: Nr. 35 | D15: Nr. 21 | F15: Nr. 22 | H15: N/A | J15: N/A | L15: N/A
A16: Calibration Due Date | B16: 45986 | D16: 46016 | F16: 46047 | H16: N/A | J16: N/A | L16: N/A
A17: Table 3; GeneXperts Used:
A18: Cepheid ID | B18: Infinity-I | D18: Infinity-V | F18: Infinity-VIII | H18: Infinity-VI | J18: N/A | L18: N/A | O18: Bag #s Tested on Inifinity | P18: N/A
A19: Calibration Due Date | B19: Dec-25 | D19: 46023 | F19: 46023 | H19: 45986 | J19: N/A | L19: N/A
A20: Cepheid ID | B20: N/A | D20: N/A | F20: N/A | H20: N/A | J20: N/A | L20: N/A
A21: Calibration Due Date | B21: N/A | D21: N/A | F21: N/A | H21: N/A | J21: N/A | L21: N/A
A22: Table 4: Single Minor Failure Mode: | I22: Table 5: Visual and Delamination Resample Results
A23: Type | C23: Original Count | D23: Result | E23: Resample Count | F23: Final Count | G23: Result | I23: Type | K23: Resample Count
A24: Invalid (w/o error code) and SPC Ct=0 | C24: =IF($B$3="","",COUNTIF('Data Summary'!$C2:$C234,"INVALID")+COUNTIF('Data Summary'!$C2:$C234,"SPC CT=0")) -> 1 | D24: =IF($B$3="","",IF(C24>Specifications!$E$5,"Resample","Pass")) -> Pass | E24: =IF($J$3="","",IF($J$3="Visual Only Resample","NA",IF($J$3="Delam and Visual Resample","NA",IF($J$3="NA","NA",(COUNTIF('Resample Data Summary'!$C8:$C234,"INVALID")+COUNTIF('Resample Data Summary'!$C8:$C234,"SPC CT=0")))))) -> NA | F24: =IF($J$3="","",IF($J$3="Visual Only Resample","NA",IF($J$3="Delam and Visual Resample","NA",IF($J$3="NA","NA",(SUM(E24+C24)))))) -> NA | G24: =IF(J3="","",IF(E24="NA","NA",IF((C24+E24)>Specifications!E6,"Fail","Pass"))) -> NA | I24: Minor Visual Failure | K24: N/A
A25: Curve Fit Error | C25: =IF($B$3="","",COUNTIF('Data Summary'!$C2:$C234, "Error 5001:*") +COUNTIF('Data Summary'!$C2:$C234, "Error 5002:*")+COUNTIF( 'Data Summary'!$C2:$C234, "Error 5003:*")+COUNTIF('Data Summary'!$C2:$C234, "Error 5004:*")+COUNTIF('Data Summary'!$C2:$C234, "Error 5005:*")+COUNTIF('Data Summary'!$C2:$C234, "Error 5015:*")+COUNTIF('Data Summary'!$C2:$C234, "Error 5016:*")) -> 0 | D25: =IF($B$3="","",IF(C25>Specifications!$E$5,"Resample","Pass")) -> Pass | E25: =IF($J$3="","",IF($J$3="Visual Only Resample","NA",IF($J$3="Delam and Visual Resample","NA",IF($J$3="NA","NA",(COUNTIF('Resample Data Summary'!$C2:$C234,"Error 5001:*")+COUNTIF('Resample Data Summary'!$C2:$C234,"Error 5002:*")+COUNTIF('Resample Data Summary'!$C2:$C234,"Error 5003:*")+COUNTIF('Resample Data Summary'!$C2:$C234,"Error 5004:*")+COUNTIF('Resample Data Summary'!$C2:$C234,"Error 5005:*")+COUNTIF('Resample Data Summary'!$C2:$C234,"Error 5015:*")+COUNTIF('Resample Data Summary'!$C2:$C234,"Error 5016:*")))))) -> NA | F25: =IF($J$3="","",IF($J$3="Visual Only Resample","NA",IF($J$3="Delam and Visual Resample","NA",IF($J$3="NA","NA",(SUM(E25+C25)))))) -> NA | G25: =IF(J3="","",IF(E25="NA","NA",IF((C25+E25)>Specifications!E6,"Fail","Pass"))) -> NA | I25: Major Visual Failure | K25: N/A
A26: Probe Check Low | C26: =IF($B$3="","",COUNTIF('Data Summary'!$C2:$C234, "Error 5007:*") +COUNTIF('Data Summary'!$C2:$C234, "Error 5017:*")+COUNTIF( 'Data Summary'!$C2:$C234, "Error 5019:*")) -> 1 | D26: =IF($B$3="","",IF(C26>Specifications!$E$5,"Resample","Pass")) -> Pass | E26: =IF($J$3="","",IF($J$3="Visual Only Resample","NA",IF($J$3="Delam and Visual Resample","NA",IF($J$3="NA","NA",(COUNTIF('Resample Data Summary'!$C2:$C234,"Error 5007:*")+COUNTIF('Resample Data Summary'!$C2:$C234,"Error 5017:*")+COUNTIF('Resample Data Summary'!$C2:$C234,"Error 5019:*")))))) -> NA | F26: =IF($J$3="","",IF($J$3="Visual Only Resample","NA",IF($J$3="Delam and Visual Resample","NA",IF($J$3="NA","NA",(SUM(E26+C26)))))) -> NA | G26: =IF(J3="","",IF(E26="NA","NA",IF((C26+E26)>Specifications!E6,"Fail","Pass"))) -> NA | I26: Delamination | K26: N/A
A27: Probe Check High | C27: =IF($B$3="","",COUNTIF('Data Summary'!$C2:$C234, "Error 5006:*") +COUNTIF('Data Summary'!$C2:$C234, "Error 5018:*")) -> 1 | D27: =IF($B$3="","",IF(C27>Specifications!$E$5,"Resample","Pass")) -> Pass | E27: =IF($J$3="","",IF($J$3="Visual Only Resample","NA",IF($J$3="Delam and Visual Resample","NA",IF($J$3="NA","NA",(COUNTIF('Resample Data Summary'!$C2:$C234,"Error 5006:*")+COUNTIF('Resample Data Summary'!$C2:$C234,"Error 5018:*")))))) -> NA | F27: =IF($J$3="","",IF($J$3="Visual Only Resample","NA",IF($J$3="Delam and Visual Resample","NA",IF($J$3="NA","NA",(SUM(E27+C27)))))) -> NA | G27: =IF(J3="","",IF(E27="NA","NA",IF((C27+E27)>Specifications!E6,"Fail","Pass"))) -> NA | I27: Note: Enter in results if applicable (all resamples other than functional and full)
A28: CIT and SLD | C28: =IF($B$3="","",COUNTIF('Data Summary'!$C2:$C234,"Error 2037*")+COUNTIF('Data Summary'!$C2:$C234,"Error 5011*")) -> 1 | D28: =IF($B$3="","",IF(C28>Specifications!$E$5,"Resample","Pass")) -> Pass | E28: =IF($J$3="","",IF($J$3="Visual Only Resample","NA",IF($J$3="Delam and Visual Resample","NA",IF($J$3="NA","NA",(COUNTIF('Resample Data Summary'!$C$8:$C$234,"Error 2037*")+COUNTIF('Resample Data Summary'!$C$8:$C$234,"Error 5011*")))))) -> NA | F28: =IF($J$3="","",IF($J$3="Visual Only Resample","NA",IF($J$3="Delam and Visual Resample","NA",IF($J$3="NA","NA",(SUM(E28+C28)))))) -> NA | G28: =IF(J3="","",IF(E28="NA","NA",IF((C28+E28)>Specifications!E6,"Fail","Pass"))) -> NA
A29: Pressure Abort or Max Pressure > 90 PSI | C29: =IF($B$3="","", COUNTIFS('Data Summary'!D10:D19,"FAIL",'Data Summary'!C10:C19,"PASS") +COUNTIFS('Data Summary'!D25:D124,"FAIL",'Data Summary'!C25:C124,"PASS") +COUNTIFS('Data Summary'!D130:D209,"FAIL",'Data Summary'!C130:C209,"PASS") +COUNTIFS('Data Summary'!D215:D234,"FAIL",'Data Summary'!C215:C234,"PASS") +COUNTIFS('Data Summary'!D10:D19,"FAIL",'Data Summary'!C10:C19,"ERROR*") +COUNTIFS('Data Summary'!D25:D124,"FAIL",'Data Summary'!C25:C124,"ERROR*") +COUNTIFS('Data Summary'!D130:D209,"FAIL",'Data Summary'!C130:C209,"ERROR*") +COUNTIFS('Data Summary'!D215:D234,"FAIL",'Data Summary'!C215:C234,"ERROR*") +COUNTIFS('Data Summary'!D10:D19,"PASS",'Data Summary'!C10:C19,"ERROR 2008*") +COUNTIFS('Data Summary'!D25:D124,"PASS",'Data Summary'!C25:C124,"ERROR 2008*") +COUNTIFS('Data Summary'!D130:D209,"PASS",'Data Summary'!C130:C209,"ERROR 2008*") +COUNTIFS('Data Summary'!D215:D234,"PASS",'Data Summary'!C215:C234,"ERROR 2008*") +COUNTIFS('Data Summary'!D10:D19,"FAIL",'Data Summary'!C10:C19,"MAJOR FUNCTIONAL") +COUNTIFS('Data Summary'!D25:D124,"FAIL",'Data Summary'!C25:C124,"MAJOR FUNCTIONAL") +COUNTIFS('Data Summary'!D130:D209,"FAIL",'Data Summary'!C130:C209,"MAJOR FUNCTIONAL") +COUNTIFS('Data Summary'!D215:D234,"FAIL",'Data Summary'!C215:C234,"MAJOR FUNCTIONAL") +COUNTIFS('Data Summary'!D10:D19,"FAIL",'Data Summary'!C10:C19,"INVALID") +COUNTIFS('Data Summary'!D25:D124,"FAIL",'Data Summary'!C25:C124,"INVALID") +COUNTIFS('Data Summary'!D130:D209,"FAIL",'Data Summary'!C130:C209,"INVALID") +COUNTIFS('Data Summary'!D215:D234,"FAIL",'Data Summary'!C215:C234,"INVALID")) -> 1 | D29: =IF($B$3="","",IF(C29>Specifications!$E$5,"Resample","Pass")) -> Pass | E29: =IF($J$3="","", IF($J$3="Visual Only Resample","NA", IF($J$3="Delam and Visual Resample","NA", IF($J$3="NA","NA", COUNTIFS('Resample Data Summary'!D10:D19,"FAIL",'Resample Data Summary'!C10:C19,"PASS") +COUNTIFS('Resample Data Summary'!D25:D124,"FAIL",'Resample Data Summary'!C25:C124,"PASS") +COUNTIFS('Resample Data Summary'!D130:D209,"FAIL",'Resample Data Summary'!C130:C209,"PASS") +COUNTIFS('Resample Data Summary'!D215:D234,"FAIL",'Resample Data Summary'!C215:C234,"PASS") +COUNTIFS('Resample Data Summary'!D10:D19,"FAIL",'Resample Data Summary'!C10:C19,"ERROR*") +COUNTIFS('Resample Data Summary'!D25:D124,"FAIL",'Resample Data Summary'!C25:C124,"ERROR*") +COUNTIFS('Resample Data Summary'!D130:D209,"FAIL",'Resample Data Summary'!C130:C209,"ERROR*") +COUNTIFS('Resample Data Summary'!D215:D234,"FAIL",'Resample Data Summary'!C215:C234,"ERROR*") +COUNTIFS('Resample Data Summary'!D10:D19,"PASS",'Resample Data Summary'!C10:C19,"ERROR 2008*") +COUNTIFS('Resample Data Summary'!D25:D124,"PASS",'Resample Data Summary'!C25:C124,"ERROR 2008*") +COUNTIFS('Resample Data Summary'!D130:D209,"PASS",'Resample Data Summary'!C130:C209,"ERROR 2008*") +COUNTIFS('Resample Data Summary'!D215:D234,"PASS",'Resample Data Summary'!C215:C234,"ERROR 2008*") +COUNTIFS('Resample Data Summary'!D10:D19,"FAIL",'Resample Data Summary'!C10:C19,"MAJOR FUNCTIONAL") +COUNTIFS('Resample Data Summary'!D25:D124,"FAIL",'Resample Data Summary'!C25:C124,"MAJOR FUNCTIONAL") +COUNTIFS('Resample Data Summary'!D130:D209,"FAIL",'Resample Data Summary'!C130:C209,"MAJOR FUNCTIONAL") +COUNTIFS('Resample Data Summary'!D215:D234,"FAIL",'Resample Data Summary'!C215:C234,"MAJOR FUNCTIONAL") +COUNTIFS('Resample Data Summary'!D10:D19,"FAIL",'Resample Data Summary'!C10:C19,"INVALID") +COUNTIFS('Resample Data Summary'!D25:D124,"FAIL",'Resample Data Summary'!C25:C124,"INVALID") +COUNTIFS('Resample Data Summary'!D130:D209,"FAIL",'Resample Data Summary'!C130:C209,"INVALID") +COUNTIFS('Resample Data Summary'!D215:D234,"FAIL",'Resample Data Summary'!C215:C234,"INVALID"))))) -> NA | F29: =IF($J$3="","",IF($J$3="Visual Only Resample","NA",IF($J$3="Delam and Visual Resample","NA",IF($J$3="NA","NA",(SUM(E29+C29)))))) -> NA | G29: =IF(J3="","",IF(E29="NA","NA",IF((C29+E29)>Specifications!E6,"Fail","Pass"))) -> NA | I29: Table 6: Major Failure Results
A30: Sample Volume Adequacy | C30: =IF($B$3="","",COUNTIF('Data Summary'!$C2:$C234,"Error 2096*")+COUNTIF('Data Summary'!$C2:$C234,"Error 2097*")+COUNTIF('Data Summary'!$C2:$C234,"Error 2125*")) -> 0 | D30: =IF($B$3="","",IF(C30>Specifications!$E$5,"Resample","Pass")) -> Pass | E30: =IF($J$3="","",IF($J$3="Visual Only Resample","NA",IF($J$3="Delam and Visual Resample","NA",IF($J$3="NA","NA",(COUNTIF('Resample Data Summary'!$C$8:$C$234,"Error 2096*")+COUNTIF('Resample Data Summary'!$C$8:$C$234,"Error 2097*")+COUNTIF('Resample Data Summary'!$C$2:$C$234,"Error 2125*")))))) -> NA | F30: =IF($J$3="","",IF($J$3="Visual Only Resample","NA",IF($J$3="Delam and Visual Resample","NA",IF($J$3="NA","NA",(SUM(E30+C30)))))) -> NA | G30: =IF(J3="","",IF(E30="NA","NA",IF((C30+E30)>Specifications!E6,"Fail","Pass"))) -> NA | I30: Type | L30: Original Count | M30: Resample Count
A31: Delamination | C31: =IF($B$3="","",COUNTIF('Data Summary'!$C2:$C234,"DELAMINATION")) -> 0 | D31: =IF($B$3="","",IF(C31>Specifications!$E$5,"Resample","Pass")) -> Pass | E31: =IF($J$3="","",IF($J$3="Visual Only Resample","NA",IF($J$3="Delam and Visual Resample",K26,IF($J$3="NA","NA",(COUNTIF('Resample Data Summary'!$C$25:$C$234,"DELAMINATION")))))) -> NA | F31: =IF($J$3="","",IF($J$3="Visual Only Resample","NA",IF($J$3="NA","NA",(SUM(E31+C31))))) -> NA | G31: =IF(J3="","",IF(E31="NA","NA",IF((C31+E31)>Specifications!E6,"Fail","Pass"))) -> NA | I31: No. False Negative | L31: =IF($B$3="","",COUNTIF('Data Summary'!$B$130:$B$209,"MTB NOT DETECTED")+COUNTIF('Data Summary'!$B$130:$B$209,"MTB DETECTED *;Rif Resistance NOT DETECTED")+COUNTIF('Data Summary'!$B$215:$B$234,"MTB NOT DETECTED")) -> 0 | M31: =IF($J$3="","",IF($J$3="Visual Only Resample","NA",IF($J$3="Delam and Visual Resample","NA",IF($J$3="NA","NA",COUNTIF('Resample Data Summary'!B130:B209,"MTB NOT DETECTED")+COUNTIF('Resample Data Summary'!B130:B209,"MTB DETECTED *;Rif Resistance NOT DETECTED")+COUNTIF('Resample Data Summary'!B215:B234,"MTB NOT DETECTED"))))) -> NA
I32: No. False Positive | L32: =IF($B$3="","",COUNTIF('Data Summary'!$B$10:$B$19,"MTB DETECTED *")+COUNTIF('Data Summary'!$B$25:$B$124,"MTB DETECTED *")+COUNTIF('Data Summary'!$B$215:$B$234,"MTB DETECTED *;Rif Resistance DETECTED")) -> 1 | M32: =IF($J$3="","",IF($J$3="Visual Only Resample","NA",IF($J$3="Delam and Visual Resample","NA",IF($J$3="NA","NA",COUNTIF('Resample Data Summary'!B25:B124,"MTB DETECTED *")+COUNTIF('Resample Data Summary'!B215:B234,"MTB DETECTED *;Rif Resistance DETECTED"))))) -> NA
I33: No. Major Visual Inspection Failures: | L33: =IF($B$3="","",COUNTIF('Data Summary'!$C:$C,"MAJOR VISUAL")) -> 0 | M33: =IF($J$3="","",IF($J$3="","0",IF($J$3="Visual Only Resample",K25,IF($J$3="Delam and Visual Resample",K25,IF($J$3="Full Resample ",COUNTIF('Resample Data Summary'!$C:$C,"MAJOR VISUAL"),IF($J$3="NA","NA",IF($J$3="Functional And Visual Resample",COUNTIF('Resample Data Summary'!$C:$C,"MAJOR VISUAL")))))))) -> NA
B34: Max Count | C34: =IF($B$3="","",IF(COUNTBLANK(C24:C31)=8,"ND",MAX(C24:C31))) -> 1 | F34: =IF(J3="","",IF(J3="NA","NA",IF(COUNTBLANK(E24:E31)+COUNTIF(E24:E31,"N*")=8,"ND",MAX(F24:F31)))) -> NA | I34: MTB Trace Detected | L34: =IF($B$3="","",COUNTIF('Data Summary'!$B$215:$B$234,"MTB Trace DETECTED;RIF Resistance INDETERMINATE")+COUNTIF('Data Summary'!$B$10:$B$19,"MTB Trace DETECTED;RIF Resistance INDETERMINATE")+COUNTIF('Data Summary'!$B$25:$B$124,"MTB Trace DETECTED;RIF Resistance INDETERMINATE")+COUNTIF('Data Summary'!$B$130:$B$209,"MTB Trace DETECTED;RIF Resistance INDETERMINATE")) -> 1 | M34: =IF($J$3="","",IF($J$3="Visual Only Resample","NA",IF($J$3="Delam and Visual Resample","NA",IF($J$3="NA","NA",COUNTIF('Resample Data Summary'!$B$215:$B$234,"MTB Trace DETECTED;RIF Resistance INDETERMINATE")+COUNTIF('Resample Data Summary'!$B$10:$B$19,"MTB Trace DETECTED;RIF Resistance INDETERMINATE")+COUNTIF('Resample Data Summary'!$B$25:$B$124,"MTB Trace DETECTED;RIF Resistance INDETERMINATE")+COUNTIF('Resample Data Summary'!$B$130:$B$209,"MTB Trace DETECTED;RIF Resistance INDETERMINATE"))))) -> NA
B36: Max Acceptable: | C36: =Specifications!$E$5 -> 4 | F36: =Specifications!$E$6 -> 10
B37: (Out of ) | C37: (210) | F37: (410)
A39: Table 7: Result Summary:
A40: Type | D40: Original Count | E40: Accept Criteria | F40: Result | H40: Resample Count | I40: Accept Criteria | J40: Combined Count | K40: Result
A41: Total No. Cartridges Registered: | D41: =IF($B$3="","",COUNTIF('Data - Replaced'!$A$2:$A$1048576,"<>")+'Data Summary'!$D$6+'Data Summary'!$D$21+'Data Summary'!$D$126+'Data Summary'!$D$211) -> 217 | E41: NA | F41: NA | H41: =IF($J$3="","",IF($J$3="Visual Only Resample","NA",IF($J$3="Delam and Visual Resample","NA",IF($J$3="NA","NA",IF($J$3="","",COUNTIF('Data - Resample Replaced'!$A$2:$A$1034,"<>")+'Resample Data Summary'!$D$21+'Resample Data Summary'!$D$126+'Resample Data Summary'!$D$211))))) -> NA | I41: NA | J41: NA | K41: NA
A42: Total No. Valid Test Replicates: | D42: =IF($B$3="","",'Data Summary'!$D$6+'Data Summary'!$D$21+'Data Summary'!$D$126+'Data Summary'!D211) -> 210 | E42: NA | F42: NA | H42: =IF($J$3="","",IF($J$3="Visual Only Resample","NA",IF($J$3="Delam and Visual Resample","NA",IF($J$3="NA","NA",('Resample Data Summary'!$D$21+'Resample Data Summary'!$D$126+'Resample Data Summary'!D211))))) -> NA | I42: NA | J42: NA | K42: NA
A43: No. Minor Failures: | D43: =IF($B$3="","", COUNTIFS('Data Summary'!D10:D19,"FAIL",'Data Summary'!C10:C19,"PASS") +COUNTIFS('Data Summary'!D25:D124,"FAIL",'Data Summary'!C25:C124,"PASS") +COUNTIFS('Data Summary'!D130:D209,"FAIL",'Data Summary'!C130:C209,"PASS") +COUNTIFS('Data Summary'!D215:D234,"FAIL",'Data Summary'!C215:C234,"PASS") +SUM(C24:C28,C30:C32) +COUNTIFS('Data Summary'!D10:D19,"FAIL",'Data Summary'!C10:C19,"ERROR 2008*") +COUNTIFS('Data Summary'!D25:D124,"FAIL",'Data Summary'!C25:C124,"ERROR 2008*") +COUNTIFS('Data Summary'!D130:D209,"FAIL",'Data Summary'!C130:C209,"ERROR 2008*") +COUNTIFS('Data Summary'!D215:D234,"FAIL",'Data Summary'!C215:C234,"ERROR 2008*") +COUNTIF('Data Summary'!C9:C234,"BARCODE FAIL") +COUNTIF('Data Summary'!C9:C234,"MINOR VISUAL") +COUNTIF('Data Summary'!C9:C234,"Indeterminate") +COUNTIFS('Data Summary'!D10:D19,"PASS",'Data Summary'!C10:C19,"ERROR 2008*") +COUNTIFS('Data Summary'!D25:D124,"PASS",'Data Summary'!C25:C124,"ERROR 2008*") +COUNTIFS('Data Summary'!D130:D209,"PASS",'Data Summary'!C130:C209,"ERROR 2008*") +COUNTIFS('Data Summary'!D215:D234,"PASS",'Data Summary'!C215:C234,"ERROR 2008*")) -> 7 | E43: NA | F43: NA | H43: =IF($J$3="","", IF($J$3="Visual Only Resample",$K$24, IF($J$3="Delam and Visual Resample",$K$26+$K$24, IF($J$3="NA","NA", COUNTIFS('Resample Data Summary'!D10:D19,"FAIL",'Resample Data Summary'!C10:C19,"PASS") +COUNTIFS('Resample Data Summary'!D25:D124,"FAIL",'Resample Data Summary'!C25:C124,"PASS") +COUNTIFS('Resample Data Summary'!D130:D209,"FAIL",'Resample Data Summary'!C130:C209,"PASS") +COUNTIFS('Resample Data Summary'!D215:D234,"FAIL",'Resample Data Summary'!C215:C234,"PASS") +SUM(E24:E28,E30:E32) +COUNTIFS('Resample Data Summary'!D10:D19,"FAIL",'Resample Data Summary'!C10:C19,"ERROR 2008*") +COUNTIFS('Resample Data Summary'!D25:D124,"FAIL",'Resample Data Summary'!C25:C124,"ERROR 2008*") +COUNTIFS('Resample Data Summary'!D130:D209,"FAIL",'Resample Data Summary'!C130:C209,"ERROR 2008*") +COUNTIFS('Resample Data Summary'!D215:D234,"FAIL",'Resample Data Summary'!C215:C234,"ERROR 2008*") +COUNTIF('Resample Data Summary'!C9:C234,"BARCODE FAIL") +COUNTIF('Resample Data Summary'!C9:C234,"MINOR VISUAL") +COUNTIF('Resample Data Summary'!C9:C234,"Indeterminate") +COUNTIFS('Resample Data Summary'!D10:D19,"PASS",'Resample Data Summary'!C10:C19,"ERROR 2008*") +COUNTIFS('Resample Data Summary'!D25:D124,"PASS",'Resample Data Summary'!C25:C124,"ERROR 2008*") +COUNTIFS('Resample Data Summary'!D130:D209,"PASS",'Resample Data Summary'!C130:C209,"ERROR 2008*") +COUNTIFS('Resample Data Summary'!D215:D234,"PASS",'Resample Data Summary'!C215:C234,"ERROR 2008*"))))) -> NA | I43: NA | J43: NA | K43: NA
A44: No. Seal Test Failures: | D44: =IF($B$3="","",SUM('Vacuum Seal Data'!D2:D251)) -> 4 | E44: =_xlfn.CONCAT("≤",LOOKUP('Test Summary'!$B$3,Specifications!$A$11:$A$22,Specifications!$H$11:$H$22)) -> ≤9 | F44: =IF($B$3="","",IF($D$44>LOOKUP($B$3,Specifications!$A$11:$A$22,Specifications!$H$11:$H$22),"Fail","Pass")) -> Pass | H44: NA | I44: NA | J44: NA | K44: NA
...

Sheet Vacuum Seal Data
B1: Cartridge ID | C1: P/F/N | D1: 0/1/NA
A2: 1 | B2: 01_0_01 | C2: P | D2: =IF(C2="","",IF(C2="N","N/A",IF(C2="P",0,IF(C2="F",1)))) -> 0
A3: 2 | B3: 01_0_02 | C3: P | D3: =IF(C3="","",IF(C3="N","N/A",IF(C3="P",0,IF(C3="F",1)))) -> 0
A4: 3 | B4: 01_0_03 | C4: P | D4: =IF(C4="","",IF(C4="N","N/A",IF(C4="P",0,IF(C4="F",1)))) -> 0
A5: 4 | B5: 01_0_04 | C5: P | D5: =IF(C5="","",IF(C5="N","N/A",IF(C5="P",0,IF(C5="F",1)))) -> 0
A6: 5 | B6: 01_0_05 | C6: P | D6: =IF(C6="","",IF(C6="N","N/A",IF(C6="P",0,IF(C6="F",1)))) -> 0
A7: 6 | B7: 01_0_06 | C7: P | D7: =IF(C7="","",IF(C7="N","N/A",IF(C7="P",0,IF(C7="F",1)))) -> 0
A8: 7 | B8: 01_0_07 | C8: P | D8: =IF(C8="","",IF(C8="N","N/A",IF(C8="P",0,IF(C8="F",1)))) -> 0
A9: 8 | B9: 01_0_08 | C9: F | D9: =IF(C9="","",IF(C9="N","N/A",IF(C9="P",0,IF(C9="F",1)))) -> 1
A10: 9 | B10: 01_0_09 | C10: P | D10: =IF(C10="","",IF(C10="N","N/A",IF(C10="P",0,IF(C10="F",1)))) -> 0
A11: 10 | B11: 01_0_10 | C11: P | D11: =IF(C11="","",IF(C11="N","N/A",IF(C11="P",0,IF(C11="F",1)))) -> 0
A12: 11 | B12: 01_1_11 | C12: P | D12: =IF(C12="","",IF(C12="N","N/A",IF(C12="P",0,IF(C12="F",1)))) -> 0
A13: 12 | B13: 01_1_12 | C13: P | D13: =IF(C13="","",IF(C13="N","N/A",IF(C13="P",0,IF(C13="F",1)))) -> 0
... A74: 73 | B74: 04_1_13 | C74: P | D74: =IF(C74="","",IF(C74="N","N/A",IF(C74="P",0,IF(C74="F",1)))) -> 0
A75: 74 | B75: 04_1_14 | C75: F | D75: 1
A76: 75 | B76: 04_1_15 | C76: P | D76: =IF(C76="","",IF(C76="N","N/A",IF(C76="P",0,IF(C76="F",1)))) -> 0
A77: 76 | B77: 04_1_16 | C77: P | D77: =IF(C77="","",IF(C77="N","N/A",IF(C77="P",0,IF(C77="F",1)))) -> 0
A78: 77 | B78: 04_1_17 | C78: P | D78: =IF(C78="","",IF(C78="N","N/A",IF(C78="P",0,IF(C78="F",1)))) -> 0
A79: 78 | B79: 04_1_18 | C79: P | D79: =IF(C79="","",IF(C79="N","N/A",IF(C79="P",0,IF(C79="F",1)))) -> 0
A80: 79 | B80: 04_2_19 | C80: P | D80: =IF(C80="","",IF(C80="N","N/A",IF(C80="P",0,IF(C80="F",1)))) -> 0
A81: 80 | B81: 04_2_20 | C81: P | D81: =IF(C81="","",IF(C81="N","N/A",IF(C81="P",0,IF(C81="F",1)))) -> 0
A82: 81 | B82: 05_0_01 | C82: P | D82: =IF(C82="","",IF(C82="N","N/A",IF(C82="P",0,IF(C82="F",1)))) -> 0
A83: 82 | B83: 05_0_02 | C83: P | D83: =IF(C83="","",IF(C83="N","N/A",IF(C83="P",0,IF(C83="F",1)))) -> 0
A84: 83 | B84: 05_0_03 | C84: P | D84: =IF(C84="","",IF(C84="N","N/A",IF(C84="P",0,IF(C84="F",1)))) -> 0
A85: 84 | B85: 05_0_04 | C85: P | D85: =IF(C85="","",IF(C85="N","N/A",IF(C85="P",0,IF(C85="F",1)))) -> 0
A86: 85 | B86: 05_0_05 | C86: P | D86: =IF(C86="","",IF(C86="N","N/A",IF(C86="P",0,IF(C86="F",1)))) -> 0
A87: 86 | B87: 05_0_06 | C87: P | D87: =IF(C87="","",IF(C87="N","N/A",IF(C87="P",0,IF(C87="F",1)))) -> 0
... A251: 250 | B251: N/A | C251: N | D251: =IF(C251="","",IF(C251="N","N/A",IF(C251="P",0,IF(C251="F",1)))) -> N/A
B254: Recorded By: | C254: Jesper Fredriksson | E254: Date: | F254: 2025 10 26
A257: Comments:
A258: N/A

Sheet Data Summary
A1: Data Summary
A2: Part No. | C2: ='Test Summary'!B3 -> GXMTBRIFULTRA50
A3: Expected Lot Number | C3: =IF('Test Summary'!$B$4="","",'Test Summary'!$B$4) -> 92303
A4: Expected Assay Name | C4: =IF('Test Summary'!$B$3="","",LOOKUP('Test Summary'!$B$3,Specifications!$A$11:$A$22,Specifications!$B$11:$B$22)) -> Xpert MTB-RIF Ultra
A6: First 10 Sample Type | B6: 0 | C6: No. Of Replicates | D6: =COUNTIF('Data - First 10'!A2:A11,"<>"&"") -> 10
A7: Lot Check | B7: =IF($C$3="","",IF($D$6=0,"NO DATA",IF(COUNTIF('Data - First 10'!$E:$E,$C$3)=$D$6,"VALID",""))) -> VALID | C7: Assay Name Check | D7: =IF($C$4="","",IF(D6=0,"NO DATA",IF(COUNTIF('Data - First 10'!$A:$A,$C$4)=D6,"VALID",""))) -> VALID
A8: No. Of Replicates Check | B8: =IF(Specifications!$B$8=$D$6,"PASS","FAIL") -> PASS | C8: Expected Result | D8: =LOOKUP($C$2,Specifications!$A$11:$A$22,Specifications!$D$11:D$22) -> MTB NOT DETECTED
A9: Cartridge ID | B9: Result | C9: Failure check | D9: Pressure Check | E9: Comment (drop-down menu available)
A10: =IF('Data - First 10'!C2="","",'Data - First 10'!C2) -> NEG_00_0_01X | B10: =IF('Data - First 10'!L2="","",'Data - First 10'!L2) -> MTB NOT DETECTED | C10: =IF(B10="","",IF(B10="INVALID",IF('Data - First 10'!GA2="","INVALID",'Data - First 10'!GA2),IF(B10="ERROR",'Data - First 10'!GA2,IF(B10="NO RESULT",'Data - First 10'!GA2,IF(B10="V","MINOR VISUAL",IF(B10="M","MAJOR VISUAL",IF(B10="B","BARCODE FAIL",IF(B10="D","DELAMINATION",IF('Data - First 10'!Q2="","DATA ENTRY ERROR",IF(B10=$D$8,"PASS","MAJOR FUNCTIONAL")))))))))) -> PASS | D10: =IF(C10="","",IF('Data - First 10'!FY2="","N/A",IF('Data - First 10'!FY2<Specifications!$D$3,"PASS","FAIL"))) -> PASS | E10: N/A
A11: =IF('Data - First 10'!C3="","",'Data - First 10'!C3) -> NEG_00_0_02X | B11: =IF('Data - First 10'!L3="","",'Data - First 10'!L3) -> MTB NOT DETECTED | C11: =IF(B11="","",IF(B11="INVALID",IF('Data - First 10'!GA3="","INVALID",'Data - First 10'!GA3),IF(B11="ERROR",'Data - First 10'!GA3,IF(B11="NO RESULT",'Data - First 10'!GA3,IF(B11="V","MINOR VISUAL",IF(B11="M","MAJOR VISUAL",IF(B11="B","BARCODE FAIL",IF(B11="D","DELAMINATION",IF('Data - First 10'!Q3="","DATA ENTRY ERROR",IF(B11=$D$8,"PASS","MAJOR FUNCTIONAL")))))))))) -> PASS | D11: =IF(C11="","",IF('Data - First 10'!FY3="","N/A",IF('Data - First 10'!FY3<Specifications!$D$3,"PASS","FAIL"))) -> PASS | E11: N/A
A12: =IF('Data - First 10'!C4="","",'Data - First 10'!C4) -> NEG_00_0_03X | B12: =IF('Data - First 10'!L4="","",'Data - First 10'!L4) -> MTB NOT DETECTED | C12: =IF(B12="","",IF(B12="INVALID",IF('Data - First 10'!GA4="","INVALID",'Data - First 10'!GA4),IF(B12="ERROR",'Data - First 10'!GA4,IF(B12="NO RESULT",'Data - First 10'!GA4,IF(B12="V","MINOR VISUAL",IF(B12="M","MAJOR VISUAL",IF(B12="B","BARCODE FAIL",IF(B12="D","DELAMINATION",IF('Data - First 10'!Q4="","DATA ENTRY ERROR",IF(B12=$D$8,"PASS","MAJOR FUNCTIONAL")))))))))) -> PASS | D12: =IF(C12="","",IF('Data - First 10'!FY4="","N/A",IF('Data - First 10'!FY4<Specifications!$D$3,"PASS","FAIL"))) -> PASS | E12: N/A
A13: =IF('Data - First 10'!C5="","",'Data - First 10'!C5) -> NEG_00_0_04X | B13: =IF('Data - First 10'!L5="","",'Data - First 10'!L5) -> MTB NOT DETECTED | C13: =IF(B13="","",IF(B13="INVALID",IF('Data - First 10'!GA5="","INVALID",'Data - First 10'!GA5),IF(B13="ERROR",'Data - First 10'!GA5,IF(B13="NO RESULT",'Data - First 10'!GA5,IF(B13="V","MINOR VISUAL",IF(B13="M","MAJOR VISUAL",IF(B13="B","BARCODE FAIL",IF(B13="D","DELAMINATION",IF('Data - First 10'!Q5="","DATA ENTRY ERROR",IF(B13=$D$8,"PASS","MAJOR FUNCTIONAL")))))))))) -> PASS | D13: =IF(C13="","",IF('Data - First 10'!FY5="","N/A",IF('Data - First 10'!FY5<Specifications!$D$3,"PASS","FAIL"))) -> PASS | E13: N/A
A14: =IF('Data - First 10'!C6="","",'Data - First 10'!C6) -> NEG_00_0_05X | B14: =IF('Data - First 10'!L6="","",'Data - First 10'!L6) -> MTB NOT DETECTED | C14: =IF(B14="","",IF(B14="INVALID",IF('Data - First 10'!GA6="","INVALID",'Data - First 10'!GA6),IF(B14="ERROR",'Data - First 10'!GA6,IF(B14="NO RESULT",'Data - First 10'!GA6,IF(B14="V","MINOR VISUAL",IF(B14="M","MAJOR VISUAL",IF(B14="B","BARCODE FAIL",IF(B14="D","DELAMINATION",IF('Data - First 10'!Q6="","DATA ENTRY ERROR",IF(B14=$D$8,"PASS","MAJOR FUNCTIONAL")))))))))) -> PASS | D14: =IF(C14="","",IF('Data - First 10'!FY6="","N/A",IF('Data - First 10'!FY6<Specifications!$D$3,"PASS","FAIL"))) -> PASS | E14: N/A
A15: =IF('Data - First 10'!C7="","",'Data - First 10'!C7) -> NEG_00_0_06+ | B15: =IF('Data - First 10'!L7="","",'Data - First 10'!L7) -> MTB NOT DETECTED | C15: =IF(B15="","",IF(B15="INVALID",IF('Data - First 10'!GA7="","INVALID",'Data - First 10'!GA7),IF(B15="ERROR",'Data - First 10'!GA7,IF(B15="NO RESULT",'Data - First 10'!GA7,IF(B15="V","MINOR VISUAL",IF(B15="M","MAJOR VISUAL",IF(B15="B","BARCODE FAIL",IF(B15="D","DELAMINATION",IF('Data - First 10'!Q7="","DATA ENTRY ERROR",IF(B15=$D$8,"PASS","MAJOR FUNCTIONAL")))))))))) -> PASS | D15: =IF(C15="","",IF('Data - First 10'!FY7="","N/A",IF('Data - First 10'!FY7<Specifications!$D$3,"PASS","FAIL"))) -> PASS | E15: N/A
A16: =IF('Data - First 10'!C8="","",'Data - First 10'!C8) -> NEG_00_0_07+ | B16: =IF('Data - First 10'!L8="","",'Data - First 10'!L8) -> MTB NOT DETECTED | C16: =IF(B16="","",IF(B16="INVALID",IF('Data - First 10'!GA8="","INVALID",'Data - First 10'!GA8),IF(B16="ERROR",'Data - First 10'!GA8,IF(B16="NO RESULT",'Data - First 10'!GA8,IF(B16="V","MINOR VISUAL",IF(B16="M","MAJOR VISUAL",IF(B16="B","BARCODE FAIL",IF(B16="D","DELAMINATION",IF('Data - First 10'!Q8="","DATA ENTRY ERROR",IF(B16=$D$8,"PASS","MAJOR FUNCTIONAL")))))))))) -> PASS | D16: =IF(C16="","",IF('Data - First 10'!FY8="","N/A",IF('Data - First 10'!FY8<Specifications!$D$3,"PASS","FAIL"))) -> PASS | E16: N/A
A17: =IF('Data - First 10'!C9="","",'Data - First 10'!C9) -> NEG_00_0_08+ | B17: =IF('Data - First 10'!L9="","",'Data - First 10'!L9) -> MTB NOT DETECTED | C17: =IF(B17="","",IF(B17="INVALID",IF('Data - First 10'!GA9="","INVALID",'Data - First 10'!GA9),IF(B17="ERROR",'Data - First 10'!GA9,IF(B17="NO RESULT",'Data - First 10'!GA9,IF(B17="V","MINOR VISUAL",IF(B17="M","MAJOR VISUAL",IF(B17="B","BARCODE FAIL",IF(B17="D","DELAMINATION",IF('Data - First 10'!Q9="","DATA ENTRY ERROR",IF(B17=$D$8,"PASS","MAJOR FUNCTIONAL")))))))))) -> PASS | D17: =IF(C17="","",IF('Data - First 10'!FY9="","N/A",IF('Data - First 10'!FY9<Specifications!$D$3,"PASS","FAIL"))) -> PASS | E17: N/A
A18: =IF('Data - First 10'!C10="","",'Data - First 10'!C10) -> NEG_00_0_09+ | B18: =IF('Data - First 10'!L10="","",'Data - First 10'!L10) -> MTB NOT DETECTED | C18: =IF(B18="","",IF(B18="INVALID",IF('Data - First 10'!GA10="","INVALID",'Data - First 10'!GA10),IF(B18="ERROR",'Data - First 10'!GA10,IF(B18="NO RESULT",'Data - First 10'!GA10,IF(B18="V","MINOR VISUAL",IF(B18="M","MAJOR VISUAL",IF(B18="B","BARCODE FAIL",IF(B18="D","DELAMINATION",IF('Data - First 10'!Q10="","DATA ENTRY ERROR",IF(B18=$D$8,"PASS","MAJOR FUNCTIONAL")))))))))) -> PASS | D18: =IF(C18="","",IF('Data - First 10'!FY10="","N/A",IF('Data - First 10'!FY10<Specifications!$D$3,"PASS","FAIL"))) -> PASS | E18: N/A
A19: =IF('Data - First 10'!C11="","",'Data - First 10'!C11) -> NEG_00_0_10+ | B19: =IF('Data - First 10'!L11="","",'Data - First 10'!L11) -> MTB NOT DETECTED | C19: =IF(B19="","",IF(B19="INVALID",IF('Data - First 10'!GA11="","INVALID",'Data - First 10'!GA11),IF(B19="ERROR",'Data - First 10'!GA11,IF(B19="NO RESULT",'Data - First 10'!GA11,IF(B19="V","MINOR VISUAL",IF(B19="M","MAJOR VISUAL",IF(B19="B","BARCODE FAIL",IF(B19="D","DELAMINATION",IF('Data - First 10'!Q11="","DATA ENTRY ERROR",IF(B19=$D$8,"PASS","MAJOR FUNCTIONAL")))))))))) -> PASS | D19: =IF(C19="","",IF('Data - First 10'!FY11="","N/A",IF('Data - First 10'!FY11<Specifications!$D$3,"PASS","FAIL"))) -> PASS | E19: N/A
A21: Sample Type | B21: 0 | C21: No. Of Replicates | D21: =COUNTIF('Data - Sample Type 0'!A2:A101,"<>"&"") -> 100
A22: Lot Check | B22: =IF($C$3="","",IF(D21=0,"NO DATA",IF(COUNTIF('Data - Sample Type 0'!$E$2:$E$101,$C$3)=D21,"VALID",""))) -> VALID | C22: Assay Name Check | D22: =IF($C$4="","",IF(D21=0,"NO DATA",IF(COUNTIF('Data - Sample Type 0'!$A$2:$A$101,$C$4)=D21,"VALID",""))) -> VALID
A23: No. Of Replicates Check | B23: =IF(Specifications!$B$6=$D$21,"PASS","FAIL") -> PASS | C23: Expected Result | D23: =LOOKUP($C$2,Specifications!$A$11:$A$22,Specifications!$D$11:D$22) -> MTB NOT DETECTED
A24: Cartridge ID | B24: Result | C24: Failure check | D24: Pressure Check | E24: Comment (drop-down menu available)
A25: =IF('Data - Sample Type 0'!C2="","",'Data - Sample Type 0'!C2) -> NEG_01_0_01X | B25: =IF('Data - Sample Type 0'!L2="","",'Data - Sample Type 0'!L2) -> MTB NOT DETECTED | C25: =IF(B25="","",IF(B25="INVALID",IF('Data - Sample Type 0'!GA2="","INVALID",'Data - Sample Type 0'!GA2),IF(B25="ERROR",'Data - Sample Type 0'!GA2,IF(B25="NO RESULT",'Data - Sample Type 0'!GA2,IF(B25="V","MINOR VISUAL",IF(B25="M","MAJOR VISUAL",IF(B25="B","BARCODE FAIL",IF(B25="D","DELAMINATION",IF('Data - Sample Type 0'!Q2="","DATA ENTRY ERROR",IF(B25=$D$23,"PASS","MAJOR FUNCTIONAL")))))))))) -> PASS | D25: =IF(C25="","",IF('Data - Sample Type 0'!FY2="","N/A",IF('Data - Sample Type 0'!FY2<Specifications!$D$3,"PASS","FAIL"))) -> PASS | E25: N/A
A26: =IF('Data - Sample Type 0'!C3="","",'Data - Sample Type 0'!C3) -> NEG_01_0_02X | B26: =IF('Data - Sample Type 0'!L3="","",'Data - Sample Type 0'!L3) -> MTB NOT DETECTED | C26: =IF(B26="","",IF(B26="INVALID",IF('Data - Sample Type 0'!GA3="","INVALID",'Data - Sample Type 0'!GA3),IF(B26="ERROR",'Data - Sample Type 0'!GA3,IF(B26="NO RESULT",'Data - Sample Type 0'!GA3,IF(B26="V","MINOR VISUAL",IF(B26="M","MAJOR VISUAL",IF(B26="B","BARCODE FAIL",IF(B26="D","DELAMINATION",IF('Data - Sample Type 0'!Q3="","DATA ENTRY ERROR",IF(B26=$D$23,"PASS","MAJOR FUNCTIONAL")))))))))) -> PASS | D26: =IF(C26="","",IF('Data - Sample Type 0'!FY3="","N/A",IF('Data - Sample Type 0'!FY3<Specifications!$D$3,"PASS","FAIL"))) -> PASS | E26: N/A
A27: =IF('Data - Sample Type 0'!C4="","",'Data - Sample Type 0'!C4) -> NEG_01_0_03X | B27: =IF('Data - Sample Type 0'!L4="","",'Data - Sample Type 0'!L4) -> MTB NOT DETECTED | C27: =IF(B27="","",IF(B27="INVALID",IF('Data - Sample Type 0'!GA4="","INVALID",'Data - Sample Type 0'!GA4),IF(B27="ERROR",'Data - Sample Type 0'!GA4,IF(B27="NO RESULT",'Data - Sample Type 0'!GA4,IF(B27="V","MINOR VISUAL",IF(B27="M","MAJOR VISUAL",IF(B27="B","BARCODE FAIL",IF(B27="D","DELAMINATION",IF('Data - Sample Type 0'!Q4="","DATA ENTRY ERROR",IF(B27=$D$23,"PASS","MAJOR FUNCTIONAL")))))))))) -> PASS | D27: =IF(C27="","",IF('Data - Sample Type 0'!FY4="","N/A",IF('Data - Sample Type 0'!FY4<Specifications!$D$3,"PASS","FAIL"))) -> PASS | E27: N/A
A28: =IF('Data - Sample Type 0'!C5="","",'Data - Sample Type 0'!C5) -> NEG_01_0_04X | B28: =IF('Data - Sample Type 0'!L5="","",'Data - Sample Type 0'!L5) -> MTB NOT DETECTED | C28: =IF(B28="","",IF(B28="INVALID",IF('Data - Sample Type 0'!GA5="","INVALID",'Data - Sample Type 0'!GA5),IF(B28="ERROR",'Data - Sample Type 0'!GA5,IF(B28="NO RESULT",'Data - Sample Type 0'!GA5,IF(B28="V","MINOR VISUAL",IF(B28="M","MAJOR VISUAL",IF(B28="B","BARCODE FAIL",IF(B28="D","DELAMINATION",IF('Data - Sample Type 0'!Q5="","DATA ENTRY ERROR",IF(B28=$D$23,"PASS","MAJOR FUNCTIONAL")))))))))) -> PASS | D28: =IF(C28="","",IF('Data - Sample Type 0'!FY5="","N/A",IF('Data - Sample Type 0'!FY5<Specifications!$D$3,"PASS","FAIL"))) -> PASS | E28: N/A
A29: =IF('Data - Sample Type 0'!C6="","",'Data - Sample Type 0'!C6) -> NEG_01_0_05X | B29: =IF('Data - Sample Type 0'!L6="","",'Data - Sample Type 0'!L6) -> MTB NOT DETECTED | C29: =IF(B29="","",IF(B29="INVALID",IF('Data - Sample Type 0'!GA6="","INVALID",'Data - Sample Type 0'!GA6),IF(B29="ERROR",'Data - Sample Type 0'!GA6,IF(B29="NO RESULT",'Data - Sample Type 0'!GA6,IF(B29="V","MINOR VISUAL",IF(B29="M","MAJOR VISUAL",IF(B29="B","BARCODE FAIL",IF(B29="D","DELAMINATION",IF('Data - Sample Type 0'!Q6="","DATA ENTRY ERROR",IF(B29=$D$23,"PASS","MAJOR FUNCTIONAL")))))))))) -> PASS | D29: =IF(C29="","",IF('Data - Sample Type 0'!FY6="","N/A",IF('Data - Sample Type 0'!FY6<Specifications!$D$3,"PASS","FAIL"))) -> PASS | E29: N/A
A30: =IF('Data - Sample Type 0'!C7="","",'Data - Sample Type 0'!C7) -> NEG_01_0_06+ | B30: =IF('Data - Sample Type 0'!L7="","",'Data - Sample Type 0'!L7) -> MTB NOT DETECTED | C30: =IF(B30="","",IF(B30="INVALID",IF('Data - Sample Type 0'!GA7="","INVALID",'Data - Sample Type 0'!GA7),IF(B30="ERROR",'Data - Sample Type 0'!GA7,IF(B30="NO RESULT",'Data - Sample Type 0'!GA7,IF(B30="V","MINOR VISUAL",IF(B30="M","MAJOR VISUAL",IF(B30="B","BARCODE FAIL",IF(B30="D","DELAMINATION",IF('Data - Sample Type 0'!Q7="","DATA ENTRY ERROR",IF(B30=$D$23,"PASS","MAJOR FUNCTIONAL")))))))))) -> PASS | D30: =IF(C30="","",IF('Data - Sample Type 0'!FY7="","N/A",IF('Data - Sample Type 0'!FY7<Specifications!$D$3,"PASS","FAIL"))) -> PASS | E30: N/A
A31: =IF('Data - Sample Type 0'!C8="","",'Data - Sample Type 0'!C8) -> NEG_01_0_07+ | B31: =IF('Data - Sample Type 0'!L8="","",'Data - Sample Type 0'!L8) -> MTB NOT DETECTED | C31: =IF(B31="","",IF(B31="INVALID",IF('Data - Sample Type 0'!GA8="","INVALID",'Data - Sample Type 0'!GA8),IF(B31="ERROR",'Data - Sample Type 0'!GA8,IF(B31="NO RESULT",'Data - Sample Type 0'!GA8,IF(B31="V","MINOR VISUAL",IF(B31="M","MAJOR VISUAL",IF(B31="B","BARCODE FAIL",IF(B31="D","DELAMINATION",IF('Data - Sample Type 0'!Q8="","DATA ENTRY ERROR",IF(B31=$D$23,"PASS","MAJOR FUNCTIONAL")))))))))) -> PASS | D31: =IF(C31="","",IF('Data - Sample Type 0'!FY8="","N/A",IF('Data - Sample Type 0'!FY8<Specifications!$D$3,"PASS","FAIL"))) -> PASS | E31: N/A
A32: =IF('Data - Sample Type 0'!C9="","",'Data - Sample Type 0'!C9) -> NEG_01_0_08A+ | B32: =IF('Data - Sample Type 0'!L9="","",'Data - Sample Type 0'!L9) -> MTB NOT DETECTED | C32: =IF(B32="","",IF(B32="INVALID",IF('Data - Sample Type 0'!GA9="","INVALID",'Data - Sample Type 0'!GA9),IF(B32="ERROR",'Data - Sample Type 0'!GA9,IF(B32="NO RESULT",'Data - Sample Type 0'!GA9,IF(B32="V","MINOR VISUAL",IF(B32="M","MAJOR VISUAL",IF(B32="B","BARCODE FAIL",IF(B32="D","DELAMINATION",IF('Data - Sample Type 0'!Q9="","DATA ENTRY ERROR",IF(B32=$D$23,"PASS","MAJOR FUNCTIONAL")))))))))) -> PASS | D32: =IF(C32="","",IF('Data - Sample Type 0'!FY9="","N/A",IF('Data - Sample Type 0'!FY9<Specifications!$D$3,"PASS","FAIL"))) -> PASS | E32: See Replaced Data
A33: =IF('Data - Sample Type 0'!C10="","",'Data - Sample Type 0'!C10) -> NEG_01_0_09+ | B33: =IF('Data - Sample Type 0'!L10="","",'Data - Sample Type 0'!L10) -> MTB NOT DETECTED | C33: =IF(B33="","",IF(B33="INVALID",IF('Data - Sample Type 0'!GA10="","INVALID",'Data - Sample Type 0'!GA10),IF(B33="ERROR",'Data - Sample Type 0'!GA10,IF(B33="NO RESULT",'Data - Sample Type 0'!GA10,IF(B33="V","MINOR VISUAL",IF(B33="M","MAJOR VISUAL",IF(B33="B","BARCODE FAIL",IF(B33="D","DELAMINATION",IF('Data - Sample Type 0'!Q10="","DATA ENTRY ERROR",IF(B33=$D$23,"PASS","MAJOR FUNCTIONAL")))))))))) -> PASS | D33: =IF(C33="","",IF('Data - Sample Type 0'!FY10="","N/A",IF('Data - Sample Type 0'!FY10<Specifications!$D$3,"PASS","FAIL"))) -> PASS | E33: N/A
A34: =IF('Data - Sample Type 0'!C11="","",'Data - Sample Type 0'!C11) -> NEG_01_0_10+ | B34: =IF('Data - Sample Type 0'!L11="","",'Data - Sample Type 0'!L11) -> MTB NOT DETECTED | C34: =IF(B34="","",IF(B34="INVALID",IF('Data - Sample Type 0'!GA11="","INVALID",'Data - Sample Type 0'!GA11),IF(B34="ERROR",'Data - Sample Type 0'!GA11,IF(B34="NO RESULT",'Data - Sample Type 0'!GA11,IF(B34="V","MINOR VISUAL",IF(B34="M","MAJOR VISUAL",IF(B34="B","BARCODE FAIL",IF(B34="D","DELAMINATION",IF('Data - Sample Type 0'!Q11="","DATA ENTRY ERROR",IF(B34=$D$23,"PASS","MAJOR FUNCTIONAL")))))))))) -> PASS | D34: =IF(C34="","",IF('Data - Sample Type 0'!FY11="","N/A",IF('Data - Sample Type 0'!FY11<Specifications!$D$3,"PASS","FAIL"))) -> PASS | E34: N/A
A35: =IF('Data - Sample Type 0'!C12="","",'Data - Sample Type 0'!C12) -> NEG_02_0_01X | B35: =IF('Data - Sample Type 0'!L12="","",'Data - Sample Type 0'!L12) -> MTB NOT DETECTED | C35: =IF(B35="","",IF(B35="INVALID",IF('Data - Sample Type 0'!GA12="","INVALID",'Data - Sample Type 0'!GA12),IF(B35="ERROR",'Data - Sample Type 0'!GA12,IF(B35="NO RESULT",'Data - Sample Type 0'!GA12,IF(B35="V","MINOR VISUAL",IF(B35="M","MAJOR VISUAL",IF(B35="B","BARCODE FAIL",IF(B35="D","DELAMINATION",IF('Data - Sample Type 0'!Q12="","DATA ENTRY ERROR",IF(B35=$D$23,"PASS","MAJOR FUNCTIONAL")))))))))) -> PASS | D35: =IF(C35="","",IF('Data - Sample Type 0'!FY12="","N/A",IF('Data - Sample Type 0'!FY12<Specifications!$D$3,"PASS","FAIL"))) -> PASS | E35: N/A
A36: =IF('Data - Sample Type 0'!C13="","",'Data - Sample Type 0'!C13) -> NEG_02_0_02X | B36: =IF('Data - Sample Type 0'!L13="","",'Data - Sample Type 0'!L13) -> MTB NOT DETECTED | C36: =IF(B36="","",IF(B36="INVALID",IF('Data - Sample Type 0'!GA13="","INVALID",'Data - Sample Type 0'!GA13),IF(B36="ERROR",'Data - Sample Type 0'!GA13,IF(B36="NO RESULT",'Data - Sample Type 0'!GA13,IF(B36="V","MINOR VISUAL",IF(B36="M","MAJOR VISUAL",IF(B36="B","BARCODE FAIL",IF(B36="D","DELAMINATION",IF('Data - Sample Type 0'!Q13="","DATA ENTRY ERROR",IF(B36=$D$23,"PASS","MAJOR FUNCTIONAL")))))))))) -> PASS | D36: =IF(C36="","",IF('Data - Sample Type 0'!FY13="","N/A",IF('Data - Sample Type 0'!FY13<Specifications!$D$3,"PASS","FAIL"))) -> PASS | E36: N/A
... A124: =IF('Data - Sample Type 0'!C101="","",'Data - Sample Type 0'!C101) -> NEG_10_0_10+ | B124: =IF('Data - Sample Type 0'!L101="","",'Data - Sample Type 0'!L101) -> MTB NOT DETECTED | C124: =IF(B124="","",IF(B124="INVALID",IF('Data - Sample Type 0'!GA101="","INVALID",'Data - Sample Type 0'!GA101),IF(B124="ERROR",'Data - Sample Type 0'!GA101,IF(B124="NO RESULT",'Data - Sample Type 0'!GA101,IF(B124="V","MINOR VISUAL",IF(B124="M","MAJOR VISUAL",IF(B124="B","BARCODE FAIL",IF(B124="D","DELAMINATION",IF('Data - Sample Type 0'!Q101="","DATA ENTRY ERROR",IF(B124=$D$23,"PASS","MAJOR FUNCTIONAL")))))))))) -> PASS | D124: =IF(C124="","",IF('Data - Sample Type 0'!FY101="","N/A",IF('Data - Sample Type 0'!FY101<Specifications!$D$3,"PASS","FAIL"))) -> PASS | E124: N/A
A126: Sample Type | B126: 1 | C126: No. Of Replicates | D126: =COUNTIF('Data - Sample Type 1'!A2:A81,"<>"&"") -> 80
A127: Lot Check | B127: =IF($C$3="","",IF(D126=0,"NO DATA",IF(COUNTIF('Data - Sample Type 1'!$E$2:$E$81,$C$3)=D126,"VALID",""))) -> VALID | C127: Assay Name Check | D127: =IF($C$4="","",IF(D126=0,"NO DATA",IF(COUNTIF('Data - Sample Type 1'!$A$2:$A$81,$C$4)=D126,"VALID",""))) -> VALID
A128: No. Of Replicates Check | B128: =IF(Specifications!$B$7=D126,"PASS","FAIL") -> PASS | C128: Expected Result | D128: =LOOKUP($C$2,Specifications!$A$11:$A$22,Specifications!$E$11:E$22) -> MTB DETECTED *;Rif Resistance DETECTED
A129: Cartridge ID | B129: Result | C129: Failure check | D129: Pressure Check | E129: Comment (drop-down menu available)
A130: =IF('Data - Sample Type 1'!C2="","",'Data - Sample Type 1'!C2) -> C15NOV23D_01_1_11X | B130: =IF('Data - Sample Type 1'!L2="","",'Data - Sample Type 1'!L2) -> MTB DETECTED LOW;RIF Resistance DETECTED | C130: =IF(B130="","",IF(B130="INVALID",IF('Data - Sample Type 1'!GA2="","INVALID",'Data - Sample Type 1'!GA2),IF(B130="ERROR",'Data - Sample Type 1'!GA2,IF(B130="NO RESULT",'Data - Sample Type 1'!GA2,IF(B130="V","MINOR VISUAL",IF(B130="M","MAJOR VISUAL",IF(B130="B","BARCODE FAIL",IF(B130="D","DELAMINATION",IF(COUNTIF(B130,Specifications!$K$4)=1,"INDETERMINATE",IF(COUNTIF(B130,$D$128)<>1,"MAJOR FUNCTIONAL",IF('Data - Sample Type 1'!Q2="","DATA ENTRY ERROR",IF('Data - Sample Type 1'!Q2=0,"SPC CT=0","PASS")))))))))))) -> PASS | D130: =IF(C130="","",IF('Data - Sample Type 1'!FY2="","N/A",IF('Data - Sample Type 1'!FY2<Specifications!$D$3,"PASS","FAIL"))) -> PASS | E130: N/A
...

Sheet Mean Ct Evaluation
G1: Sample Type 0 (Negative) | N1: Sample Type 1 (TBMDR2) | AA1: Sample Type 2 (TBWT)
A2: Data Set | B2: IS1081-IS6110 Ct | C2: IS1081-IS6110 Ct Mean | D2: SPC Ct | E2: SPC Ct Mean | G2: Data Set | H2: IS1081-IS6110 Ct | I2: IS1081-IS6110 Ct Mean per Data Set | J2: SPC Ct | K2: SPC mean per Data Set | N2: Data Set | O2: IS1081-IS6110 Ct | P2: rpo1 Ct | Q2: rpo2 Ct | R2: rpo4 Ct | S2: rpo1 Tm | T2: rpo1 Tm Mean | U2: rpo2 Tm | V2: rpo2 Tm Mean | W2: rpo4 Tm | X2: rpo4 Tm Mean | AA2: Data Set | AB2: IS1081-IS6110 Ct | AC2: rpo1 Ct | AD2: rpo2 Ct | AE2: rpo3 Ct | AF2: rpo4 Ct | AG2: rpo1 Tm | AH2: rpo1 Tm Mean | AI2: rpo2 Tm | AJ2: rpo2 Tm Mean | AK2: rpo3 Tm | AL2: rpo3 Tm Mean | AM2: rpo4 Tm | AN2: rpo4 Tm Mean
A3: First 10 | B3: =IF('Data Summary'!C10="PASS",IF('Data - First 10'!AE2=0,40,'Data - First 10'!AE2),"") -> 40 | C3: =ROUND(AVERAGE(B3:B12),1) -> 40 | D3: =IF('Data Summary'!C10="PASS",'Data - First 10'!Q2,"") -> 24.3 | E3: =ROUND(AVERAGE(D3:D12),1) -> 24 | G3: 1 | H3: =IF('Data Summary'!C25="PASS",IF('Data - Sample Type 0'!AE2=0,40,'Data - Sample Type 0'!AE2),"") -> 40 | I3: =ROUND(AVERAGE(H3:H12),1) -> 40 | J3: =IF('Data Summary'!C25="PASS",IF('Data Summary'!A25="","",'Data - Sample Type 0'!Q2),"") -> 26.3 | K3: =ROUND(AVERAGE(J3:J12),1) -> 24.7 | N3: 1 | O3: =IF('Data Summary'!C130="PASS",IF('Data - Sample Type 1'!AE2=0,40,'Data - Sample Type 1'!AE2),"") -> 27.2 | P3: =IF('Data Summary'!C130="PASS",IF('Data - Sample Type 1'!AS2=0,40,'Data - Sample Type 1'!AS2),"") -> 25 | Q3: =IF('Data Summary'!C130="PASS",IF('Data - Sample Type 1'!BG2=0,40,'Data - Sample Type 1'!BG2),"") -> 25.9 | R3: =IF('Data Summary'!C130="PASS",IF('Data - Sample Type 1'!CI2=0,40,'Data - Sample Type 1'!CI2),"") -> 23.5 | S3: =IF('Data Summary'!C130="PASS",'Data - Sample Type 1'!DK2,"") -> 69.3 | T3: =ROUND(AVERAGE(S3:S10),1) -> 69.2 | U3: =IF('Data Summary'!C130="PASS",'Data - Sample Type 1'!EY2,"") -> 70 | V3: =ROUND(AVERAGE(U3:U10),1) -> 69.9 | W3: =IF('Data Summary'!C130="PASS",'Data - Sample Type 1'!FO2,"") -> 73.5 | X3: =ROUND(AVERAGE(W3:W10),1) -> 73.5 | AA3: 1-5 | AB3: =IF('Data Summary'!C215="PASS",IF('Data - Sample Type 2'!AE2=0,40,'Data - Sample Type 2'!AE2),"") -> 22.4 | AC3: =IF('Data Summary'!C215="PASS",IF('Data - Sample Type 2'!AS2=0,40,'Data - Sample Type 2'!AS2),"") -> 24.7 | AD3: =IF('Data Summary'!C215="PASS",IF('Data - Sample Type 2'!BG2=0,40,'Data - Sample Type 2'!BG2),"") -> 25 | AE3: =IF('Data Summary'!C215="PASS",IF('Data - Sample Type 2'!BU2=0,40,'Data - Sample Type 2'!BU2),"") -> 25.8 | AF3: =IF('Data Summary'!C215="PASS",IF('Data - Sample Type 2'!CI2=0,40,'Data - Sample Type 2'!CI2),"") -> 27.2 | AG3: =IF('Data Summary'!C215="PASS",'Data - Sample Type 2'!DK2,"") -> 69 | AH3: =ROUND(AVERAGE(AG3:AG12),1) -> 69.1 | AI3: =IF('Data Summary'!C215="PASS",'Data - Sample Type 2'!EY2,"") -> 0 | AJ3: =ROUND(AVERAGE(AI3:AI12),1) -> 0 | AK3: =IF('Data Summary'!C215="PASS",'Data - Sample Type 2'!EA2,"") -> 75.5 | AL3: =ROUND(AVERAGE(AK3:AK12),1) -> 75.6 | AM3: =IF('Data Summary'!C215="PASS",'Data - Sample Type 2'!EI2,"") -> 66.8 | AN3: =ROUND(AVERAGE(AM3:AM12),1) -> 66.9
B4: =IF('Data Summary'!C11="PASS",IF('Data - First 10'!AE3=0,40,'Data - First 10'!AE3),"") -> 40 | D4: =IF('Data Summary'!C11="PASS",'Data - First 10'!Q3,"") -> 24.3 | H4: =IF('Data Summary'!C26="PASS",IF('Data - Sample Type 0'!AE3=0,40,'Data - Sample Type 0'!AE3),"") -> 40 | J4: =IF('Data Summary'!C26="PASS",IF('Data Summary'!A26="","",'Data - Sample Type 0'!Q3),"") -> 24 | O4: =IF('Data Summary'!C131="PASS",IF('Data - Sample Type 1'!AE3=0,40,'Data - Sample Type 1'!AE3),"") -> 25.6 | P4: =IF('Data Summary'!C131="PASS",IF('Data - Sample Type 1'!AS3=0,40,'Data - Sample Type 1'!AS3),"") -> 23.5 | Q4: =IF('Data Summary'!C131="PASS",IF('Data - Sample Type 1'!BG3=0,40,'Data - Sample Type 1'!BG3),"") -> 24.8 | R4: =IF('Data Summary'!C131="PASS",IF('Data - Sample Type 1'!CI3=0,40,'Data - Sample Type 1'!CI3),"") -> 22.3 | S4: =IF('Data Summary'!C131="PASS",'Data - Sample Type 1'!DK3,"") -> 69.2 | U4: =IF('Data Summary'!C131="PASS",'Data - Sample Type 1'!EY3,"") -> 70 | W4: =IF('Data Summary'!C131="PASS",'Data - Sample Type 1'!FO3,"") -> 73.5 | AB4: =IF('Data Summary'!C216="PASS",IF('Data - Sample Type 2'!AE3=0,40,'Data - Sample Type 2'!AE3),"") -> 21.1 | AC4: =IF('Data Summary'!C216="PASS",IF('Data - Sample Type 2'!AS3=0,40,'Data - Sample Type 2'!AS3),"") -> 23.6 | AD4: =IF('Data Summary'!C216="PASS",IF('Data - Sample Type 2'!BG3=0,40,'Data - Sample Type 2'!BG3),"") -> 23.6 | AE4: =IF('Data Summary'!C216="PASS",IF('Data - Sample Type 2'!BU3=0,40,'Data - Sample Type 2'!BU3),"") -> 24.7 | AF4: =IF('Data Summary'!C216="PASS",IF('Data - Sample Type 2'!CI3=0,40,'Data - Sample Type 2'!CI3),"") -> 25.8 | AG4: =IF('Data Summary'!C216="PASS",'Data - Sample Type 2'!DK3,"") -> 69 | AI4: =IF('Data Summary'!C216="PASS",'Data - Sample Type 2'!EY3,"") -> 0 | AK4: =IF('Data Summary'!C216="PASS",'Data - Sample Type 2'!EA3,"") -> 75.5 | AM4: =IF('Data Summary'!C216="PASS",'Data - Sample Type 2'!EI3,"") -> 66.9
B5: =IF('Data Summary'!C12="PASS",IF('Data - First 10'!AE4=0,40,'Data - First 10'!AE4),"") -> 40 | D5: =IF('Data Summary'!C12="PASS",'Data - First 10'!Q4,"") -> 24.5 | H5: =IF('Data Summary'!C27="PASS",IF('Data - Sample Type 0'!AE4=0,40,'Data - Sample Type 0'!AE4),"") -> 40 | J5: =IF('Data Summary'!C27="PASS",IF('Data Summary'!A27="","",'Data - Sample Type 0'!Q4),"") -> 23.9 | O5: =IF('Data Summary'!C132="PASS",IF('Data - Sample Type 1'!AE4=0,40,'Data - Sample Type 1'!AE4),"") -> 26.3 | P5: =IF('Data Summary'!C132="PASS",IF('Data - Sample Type 1'!AS4=0,40,'Data - Sample Type 1'!AS4),"") -> 23.5 | Q5: =IF('Data Summary'!C132="PASS",IF('Data - Sample Type 1'!BG4=0,40,'Data - Sample Type 1'!BG4),"") -> 24.6 | R5: =IF('Data Summary'!C132="PASS",IF('Data - Sample Type 1'!CI4=0,40,'Data - Sample Type 1'!CI4),"") -> 22.2 | S5: =IF('Data Summary'!C132="PASS",'Data - Sample Type 1'!DK4,"") -> 69.1 | U5: =IF('Data Summary'!C132="PASS",'Data - Sample Type 1'!EY4,"") -> 69.9 | W5: =IF('Data Summary'!C132="PASS",'Data - Sample Type 1'!FO4,"") -> 73.4 | AB5: =IF('Data Summary'!C217="PASS",IF('Data - Sample Type 2'!AE4=0,40,'Data - Sample Type 2'!AE4),"") -> 23.1 | AC5: =IF('Data Summary'!C217="PASS",IF('Data - Sample Type 2'!AS4=0,40,'Data - Sample Type 2'!AS4),"") -> 25 | AD5: =IF('Data Summary'!C217="PASS",IF('Data - Sample Type 2'!BG4=0,40,'Data - Sample Type 2'!BG4),"") -> 25.1 | AE5: =IF('Data Summary'!C217="PASS",IF('Data - Sample Type 2'!BU4=0,40,'Data - Sample Type 2'!BU4),"") -> 26.4 | AF5: =IF('Data Summary'!C217="PASS",IF('Data - Sample Type 2'!CI4=0,40,'Data - Sample Type 2'!CI4),"") -> 27.4 | AG5: =IF('Data Summary'!C217="PASS",'Data - Sample Type 2'!DK4,"") -> 69.3 | AI5: =IF('Data Summary'!C217="PASS",'Data - Sample Type 2'!EY4,"") -> 0 | AK5: =IF('Data Summary'!C217="PASS",'Data - Sample Type 2'!EA4,"") -> 75.8 | AM5: =IF('Data Summary'!C217="PASS",'Data - Sample Type 2'!EI4,"") -> 67
B6: =IF('Data Summary'!C13="PASS",IF('Data - First 10'!AE5=0,40,'Data - First 10'!AE5),"") -> 40 | D6: =IF('Data Summary'!C13="PASS",'Data - First 10'!Q5,"") -> 23.2 | H6: =IF('Data Summary'!C28="PASS",IF('Data - Sample Type 0'!AE5=0,40,'Data - Sample Type 0'!AE5),"") -> 40 | J6: =IF('Data Summary'!C28="PASS",IF('Data Summary'!A28="","",'Data - Sample Type 0'!Q5),"") -> 23.7 | O6: =IF('Data Summary'!C133="PASS",IF('Data - Sample Type 1'!AE5=0,40,'Data - Sample Type 1'!AE5),"") -> 26.4 | P6: =IF('Data Summary'!C133="PASS",IF('Data - Sample Type 1'!AS5=0,40,'Data - Sample Type 1'!AS5),"") -> 23.8 | Q6: =IF('Data Summary'!C133="PASS",IF('Data - Sample Type 1'!BG5=0,40,'Data - Sample Type 1'!BG5),"") -> 24.9 | R6: =IF('Data Summary'!C133="PASS",IF('Data - Sample Type 1'!CI5=0,40,'Data - Sample Type 1'!CI5),"") -> 22.6 | S6: =IF('Data Summary'!C133="PASS",'Data - Sample Type 1'!DK5,"") -> 69.1 | U6: =IF('Data Summary'!C133="PASS",'Data - Sample Type 1'!EY5,"") -> 69.8 | W6: =IF('Data Summary'!C133="PASS",'Data - Sample Type 1'!FO5,"") -> 73.3 | AB6: =IF('Data Summary'!C218="PASS",IF('Data - Sample Type 2'!AE5=0,40,'Data - Sample Type 2'!AE5),"") -> 23.8 | AC6: =IF('Data Summary'!C218="PASS",IF('Data - Sample Type 2'!AS5=0,40,'Data - Sample Type 2'!AS5),"") -> 26.1 | AD6: =IF('Data Summary'!C218="PASS",IF('Data - Sample Type 2'!BG5=0,40,'Data - Sample Type 2'!BG5),"") -> 26.3 | AE6: =IF('Data Summary'!C218="PASS",IF('Data - Sample Type 2'!BU5=0,40,'Data - Sample Type 2'!BU5),"") -> 27.8 | AF6: =IF('Data Summary'!C218="PASS",IF('Data - Sample Type 2'!CI5=0,40,'Data - Sample Type 2'!CI5),"") -> 28.7 | AG6: =IF('Data Summary'!C218="PASS",'Data - Sample Type 2'!DK5,"") -> 69 | AI6: =IF('Data Summary'!C218="PASS",'Data - Sample Type 2'!EY5,"") -> 0 | AK6: =IF('Data Summary'!C218="PASS",'Data - Sample Type 2'!EA5,"") -> 75.4 | AM6: =IF('Data Summary'!C218="PASS",'Data - Sample Type 2'!EI5,"") -> 66.6
B7: =IF('Data Summary'!C14="PASS",IF('Data - First 10'!AE6=0,40,'Data - First 10'!AE6),"") -> 40 | D7: =IF('Data Summary'!C14="PASS",'Data - First 10'!Q6,"") -> 21.6 | H7: =IF('Data Summary'!C29="PASS",IF('Data - Sample Type 0'!AE6=0,40,'Data - Sample Type 0'!AE6),"") -> 40 | J7: =IF('Data Summary'!C29="PASS",IF('Data Summary'!A29="","",'Data - Sample Type 0'!Q6),"") -> 27.1 | O7: =IF('Data Summary'!C134="PASS",IF('Data - Sample Type 1'!AE6=0,40,'Data - Sample Type 1'!AE6),"") -> 26.8 | P7: =IF('Data Summary'!C134="PASS",IF('Data - Sample Type 1'!AS6=0,40,'Data - Sample Type 1'!AS6),"") -> 24 | Q7: =IF('Data Summary'!C134="PASS",IF('Data - Sample Type 1'!BG6=0,40,'Data - Sample Type 1'!BG6),"") -> 24.7 | R7: =IF('Data Summary'!C134="PASS",IF('Data - Sample Type 1'!CI6=0,40,'Data - Sample Type 1'!CI6),"") -> 22.6 | S7: =IF('Data Summary'!C134="PASS",'Data - Sample Type 1'!DK6,"") -> 69.2 | T7: =IF(COUNTIF(S3:S10,">0")=8-COUNTIF(S3:S10,""),"PASS","FAIL") -> PASS | U7: =IF('Data Summary'!C134="PASS",'Data - Sample Type 1'!EY6,"") -> 69.8 | V7: =IF(COUNTIF(U3:U10,">0")=8-COUNTIF(U3:U10,""),"PASS","FAIL") -> PASS | W7: =IF('Data Summary'!C134="PASS",'Data - Sample Type 1'!FO6,"") -> 73.4 | X7: =IF(COUNTIF(W3:W10,">0")=8-COUNTIF(W3:W10,""),"PASS","FAIL") -> PASS | AB7: =IF('Data Summary'!C219="PASS",IF('Data - Sample Type 2'!AE6=0,40,'Data - Sample Type 2'!AE6),"") | AC7: =IF('Data Summary'!C219="PASS",IF('Data - Sample Type 2'!AS6=0,40,'Data - Sample Type 2'!AS6),"") | AD7: =IF('Data Summary'!C219="PASS",IF('Data - Sample Type 2'!BG6=0,40,'Data - Sample Type 2'!BG6),"") | AE7: =IF('Data Summary'!C219="PASS",IF('Data - Sample Type 2'!BU6=0,40,'Data - Sample Type 2'!BU6),"") | AF7: =IF('Data Summary'!C219="PASS",IF('Data - Sample Type 2'!CI6=0,40,'Data - Sample Type 2'!CI6),"") | AG7: =IF('Data Summary'!C219="PASS",'Data - Sample Type 2'!DK6,"") | AI7: =IF('Data Summary'!C219="PASS",'Data - Sample Type 2'!EY6,"") | AK7: =IF('Data Summary'!C219="PASS",'Data - Sample Type 2'!EA6,"") | AM7: =IF('Data Summary'!C219="PASS",'Data - Sample Type 2'!EI6,"")
B8: =IF('Data Summary'!C15="PASS",IF('Data - First 10'!AE7=0,40,'Data - First 10'!AE7),"") -> 40 | C8: =IF(C3>=Specifications!$D$26,"PASS","FAIL") -> PASS | D8: =IF('Data Summary'!C15="PASS",'Data - First 10'!Q7,"") -> 23.9 | E8: =IF(E3<=Specifications!$B$26,"PASS","FAIL") -> PASS | H8: =IF('Data Summary'!C30="PASS",IF('Data - Sample Type 0'!AE7=0,40,'Data - Sample Type 0'!AE7),"") -> 40 | I8: =IF(I3>=Specifications!$D$26,"PASS","FAIL") -> PASS | J8: =IF('Data Summary'!C30="PASS",IF('Data Summary'!A30="","",'Data - Sample Type 0'!Q7),"") -> 23.6 | K8: =IF(K3<=Specifications!$B$26,"PASS","FAIL") -> PASS | O8: =IF('Data Summary'!C135="PASS",IF('Data - Sample Type 1'!AE7=0,40,'Data - Sample Type 1'!AE7),"") -> 26.2 | P8: =IF('Data Summary'!C135="PASS",IF('Data - Sample Type 1'!AS7=0,40,'Data - Sample Type 1'!AS7),"") -> 23.4 | Q8: =IF('Data Summary'!C135="PASS",IF('Data - Sample Type 1'!BG7=0,40,'Data - Sample Type 1'!BG7),"") -> 24.6 | R8: =IF('Data Summary'!C135="PASS",IF('Data - Sample Type 1'!CI7=0,40,'Data - Sample Type 1'!CI7),"") -> 22.4 | S8: =IF('Data Summary'!C135="PASS",'Data - Sample Type 1'!DK7,"") -> 69.4 | U8: =IF('Data Summary'!C135="PASS",'Data - Sample Type 1'!EY7,"") -> 70.1 | W8: =IF('Data Summary'!C135="PASS",'Data - Sample Type 1'!FO7,"") -> 73.6 | AB8: =IF('Data Summary'!C220="PASS",IF('Data - Sample Type 2'!AE7=0,40,'Data - Sample Type 2'!AE7),"") -> 24.4 | AC8: =IF('Data Summary'!C220="PASS",IF('Data - Sample Type 2'!AS7=0,40,'Data - Sample Type 2'!AS7),"") -> 25.2 | AD8: =IF('Data Summary'!C220="PASS",IF('Data - Sample Type 2'!BG7=0,40,'Data - Sample Type 2'!BG7),"") -> 25.2 | AE8: =IF('Data Summary'!C220="PASS",IF('Data - Sample Type 2'!BU7=0,40,'Data - Sample Type 2'!BU7),"") -> 26.1 | AF8: =IF('Data Summary'!C220="PASS",IF('Data - Sample Type 2'!CI7=0,40,'Data - Sample Type 2'!CI7),"") -> 27.4 | AG8: =IF('Data Summary'!C220="PASS",'Data - Sample Type 2'!DK7,"") -> 69.2 | AH8: =IF(COUNTIF('Data - Sample Type 2'!$A$2:$A$11,"<>"&"")>=10,IF(COUNTIF(AG3:AG12,">0")=10-COUNTIF(AG3:AG12,""),"PASS","FAIL"),"Not enough data") -> PASS | AI8: =IF('Data Summary'!C220="PASS",'Data - Sample Type 2'!EY7,"") -> 0 | AJ8: =IF(COUNTIF('Data - Sample Type 2'!$A$2:$A$11,"<>"&"")>=10,IF(COUNTIF(AI3:AI12,"=0")=10-COUNTIF(AI3:AI12,""),"PASS","FAIL"),"Not enough data") -> PASS | AK8: =IF('Data Summary'!C220="PASS",'Data - Sample Type 2'!EA7,"") -> 75.7 | AL8: =IF(COUNTIF('Data - Sample Type 2'!$A$2:$A$11,"<>"&"")>=10,IF(COUNTIF(AK3:AK12,">0")=10-COUNTIF(AK3:AK12,""),"PASS","FAIL"),"Not enough data") -> PASS | AM8: =IF('Data Summary'!C220="PASS",'Data - Sample Type 2'!EI7,"") -> 67 | AN8: =IF(COUNTIF('Data - Sample Type 2'!$A$2:$A$11,"<>"&"")>=10,IF(COUNTIF(AM3:AM12,">0")=10-COUNTIF(AM3:AM12,""),"PASS","FAIL"),"Not enough data") -> PASS
